<mujoco model="RMInfantry_Complation_Vision.SLDASM">
  <compiler angle="radian" meshdir="../meshes/"/>

  <default>
    <default class="RMInfantry_wheelLegged">
      <geom type="mesh"/>
      <joint damping="1" armature="0.1"/>
      <default class="visual">
        <geom contype="0" conaffinity="0" group="2"/>
      </default>
      <default class="collision">
        <geom group="3" mass="0" density="0"/>
      </default>
      <default class="collision1">
        <geom group="4" mass="0" density="0"/>
      </default>
      <site size="0.001" rgba="0.5 0.5 0.5 0.3" group="4"/>
    </default>
  </default>

  <default>
    <default class='hip_joint'>
        <joint damping="0.035" frictionloss="0.023" armature="0.0"/>
    </default> 
    <default class='wheel_joint'>
        <joint damping="0.01" frictionloss="0.05" armature="0.0"/>
    </default> 
    <default class='gimbal_pitch_joint'>
        <joint damping="0.004" frictionloss="0.016" armature="0.0"/>
    </default> 
    <default class='gimbal_yaw_joint'>
        <joint damping="0.012" frictionloss="0.009" armature="0.0"/>
    </default> 
    <default class='frition_wheel_joint'>
        <joint damping="0.002" frictionloss="0.009" armature="0.0"/>
    </default> 
    <default class='feeder_desk_joint'>
        <joint damping="0.002" frictionloss="0.009" armature="0.0"/>
    </default> 
  </default>

  <default>
    <default class='Motorevo_PA100_motor'>
        <motor ctrlrange="-50 50"/>
    </default> 
    <default class='KTECH_MF9025V2_motor'>
        <motor ctrlrange="-10 10"/>
    </default> 
    <default class='DJI_GM6020_motor'>
        <motor ctrlrange="-5 5"/>
    </default> 
    <default class='DJI_M2006_motor'>
        <motor ctrlrange="-5 5"/>
    </default> 
    <default class='DJI_M3508_motor'>
        <motor ctrlrange="-10 10"/>
    </default> 
  </default>

  <asset>
    <mesh name="base_link" file="base_link.obj"/>
    <mesh name="left_front_hip_link" file="left_front_hip_link.STL"/>
    <mesh name="left_front_knee_link" file="left_front_knee_link.STL"/>
    <mesh name="left_rear_hip_link" file="left_rear_hip_link.STL"/>
    <mesh name="left_rear_knee_link" file="left_rear_knee_link.STL"/>
    <mesh name="left_chassis_wheel_link" file="left_chassis_wheel_link.STL"/>
    <mesh name="right_front_hip_link" file="right_front_hip_link.STL"/>
    <mesh name="right_front_knee_link" file="right_front_knee_link.STL"/>
    <mesh name="right_rear_hip_link" file="right_rear_hip_link.STL"/>
    <mesh name="right_rear_knee_link" file="right_rear_knee_link.STL"/>
    <mesh name="right_chassis_wheel_link" file="right_chassis_wheel_link.STL"/>
    <mesh name="gimbal_yaw_link" file="gimbal_yaw_link.STL"/>
    <mesh name="gimbal_pitch_motor_link" file="gimbal_pitch_motor_link.STL"/>
    <mesh name="gimbal_pitch_motor_chrild1_link" file="gimbal_pitch_motor_chrild1_link.STL"/>
    <mesh name="gimbal_pitch_motor_chrild2_link" file="gimbal_pitch_motor_chrild2_link.STL"/>
    <mesh name="gimbal_pitch_link" file="gimbal_pitch_link.STL"/>
    <mesh name="left_frition_wheel_link" file="left_frition_wheel_link.STL"/>
    <mesh name="right_frition_wheel_link" file="right_frition_wheel_link.STL"/>
    <mesh name="feeder_desk_link" file="feeder_desk_link.STL"/>
  </asset>

  <worldbody>
    <body name="base_link" pos="0 0 0.1" childclass="RMInfantry_wheelLegged">
      <inertial pos="-0.003111 0.0015208 0.10627" quat="0.00205399 0.707016 0.00191127 0.707192" mass="9.774" diaginertia="0.0548401 0.0519599 0.018047"/>
      <joint name="floating_base_joint" type="free"/>
      <geom type="mesh" contype="0" conaffinity="0" group="1" density="0" rgba="0.50196 0.50196 0.50196 1" mesh="base_link"/>
      <geom type="box"  size="0.265 0.1 0.1" pos="0 0 0.1"rgba="1 0.0 0.0 1"  class="collision"/>
      <site name="imu" pos="0 0 0"/>
      <body name="left_front_hip_link" pos="0.065 0.1423 0.127">
        <inertial pos="0.032281 0.032438 0.011151" quat="0.574502 0.412247 0.412247 0.574502" mass="0.2528" diaginertia="0.00064137 0.000572305 8.22754e-05"/>
        <joint name="left_front_hip_joint" pos="0 0 0" axis="0 1 0" range="0 1.48353" class='hip_joint'/>
        <geom type="mesh" contype="0" conaffinity="0" group="1" density="0" rgba="0.89804 0.91373 0.92549 1" mesh="left_front_hip_link"/>
        <body name="left_front_knee_link" pos="0.12968 0.0194 0.047199">
          <inertial pos="-0.089345 0.006 -0.086713" quat="0.646507 0.286406 0.286406 0.646507" mass="0.21937" diaginertia="0.0018691 0.00181967 5.46815e-05"/>
          <joint name="left_front_knee_joint" pos="0 0 0" axis="0 1 0"/>

          <site name="left_front_knee_site1" pos="-0.19468 0.0245 -0.17534" size="0.005" rgba="1 0 0 1"/>

          <geom type="mesh" contype="0" conaffinity="0" group="1" density="0" rgba="1 1 1 1" mesh="left_front_knee_link"/>
        </body>
      </body>
      <body name="left_rear_hip_link" pos="-0.065 0.1423 0.127">
        <inertial pos="-0.0369979 0.0309983 0.0127966" quat="0.410443 0.575792 0.575792 0.410443" mass="0.25817" diaginertia="0.000715454 0.00064611 8.05428e-05"/>
        <joint name="left_rear_hip_joint" pos="0 0 0" axis="0 1 0" range="-1.48353 0" class='hip_joint'/>
        <geom type="mesh" contype="0" conaffinity="0" group="1" density="0" rgba="0.898039 0.913725 0.92549 1" mesh="left_rear_hip_link"/>
        <body name="left_rear_knee_link" pos="-0.12968 0.0309 0.047199">
          <inertial pos="0.10163 0.02 -0.097327" quat="0.28954 0.64511 0.64511 0.28954" mass="0.2214" diaginertia="0.0021043 0.00201488 9.47394e-05"/>
          <joint name="left_rear_knee_joint" pos="0 0 0" axis="0 1 0"/>
          <geom type="mesh" contype="0" conaffinity="0" group="1" density="0" rgba="1 1 1 1" mesh="left_rear_knee_link"/>
          <body name="left_chassis_wheel_link" pos="0.19468 0.013 -0.17534">
            <inertial pos="-5.5954e-06 0.036068 -3.5474e-06" quat="0.270622 0.653296 0.653256 0.270601" mass="0.52417" diaginertia="0.0011204 0.000600313 0.000600287"/>
            <joint name="left_chassis_wheel_joint" pos="0 0 0" axis="0 1 0" class='wheel_joint'/>
            <site name="left_chassis_wheel_site1" pos="0 0 0" size="0.005" rgba="1 0 0 1"/>
            <geom type="mesh" contype="0" conaffinity="0" group="1" density="0" rgba="1 1 1 1" mesh="left_chassis_wheel_link"/>
            <geom type="mesh" rgba="1 1 1 1" mesh="left_chassis_wheel_link" class="collision"/>
          </body>
        </body>
      </body>
      <body name="right_front_hip_link" pos="0.065 -0.1423 0.127">
        <inertial pos="0.032281 -0.032438 0.011151" quat="0.574502 0.412247 0.412247 0.574502" mass="0.2528" diaginertia="0.00064137 0.000572305 8.22754e-05"/>
        <joint name="right_front_hip_joint" pos="0 0 0" axis="0 -1 0" range="-1.48353 0" class='hip_joint'/>
        <geom type="mesh" contype="0" conaffinity="0" group="1" density="0" rgba="1 1 1 1" mesh="right_front_hip_link"/>
        <body name="right_front_knee_link" pos="0.12968 -0.0194 0.047199">
          <inertial pos="-0.089345 -0.006 -0.086713" quat="0.646507 0.286406 0.286406 0.646507" mass="0.21937" diaginertia="0.0018691 0.00181967 5.46815e-05"/>
          <joint name="right_front_knee_joint" pos="0 0 0" axis="0 -1 0"/>
          <site name="right_front_knee_site1" pos="-0.19468 -0.0245 -0.17534" size="0.005" rgba="1 0 0 1"/>
          <geom type="mesh" contype="0" conaffinity="0" group="1" density="0" rgba="1 1 1 1" mesh="right_front_knee_link"/>
        </body>
      </body>
      <body name="right_rear_hip_link" pos="-0.065 -0.1423 0.127">
        <inertial pos="-0.036998 -0.030998 0.012797" quat="0.410444 0.575791 0.575791 0.410444" mass="0.25817" diaginertia="0.00071545 0.000646109 8.0541e-05"/>
        <joint name="right_rear_hip_joint" pos="0 0 0" axis="0 -1 0" range="0 1.48353" class='hip_joint'/>
        <geom type="mesh" contype="0" conaffinity="0" group="1" density="0" rgba="0.89804 0.91373 0.92549 1" mesh="right_rear_hip_link"/>
        <body name="right_rear_knee_link" pos="-0.12968 -0.0309 0.047199">
          <inertial pos="0.10163 -0.02 -0.097327" quat="0.28954 0.64511 0.64511 0.28954" mass="0.2214" diaginertia="0.0021043 0.00201488 9.47394e-05"/>
          <joint name="right_rear_knee_joint" pos="0 0 0" axis="0 -1 0"/>
          <geom type="mesh" contype="0" conaffinity="0" group="1" density="0" rgba="1 1 1 1" mesh="right_rear_knee_link"/>
          <body name="right_chassis_wheel_link" pos="0.19468 -0.013 -0.17534">
            <inertial pos="1.7764e-06 -0.036068 6.3825e-06" quat="0.402989 0.581024 0.581013 0.403032" mass="0.52417" diaginertia="0.0011204 0.000600313 0.000600287"/>
            <joint name="right_chassis_wheel_joint" pos="0 0 0" axis="0 -1 0" class='wheel_joint'/>
            <site name="right_chassis_wheel_site1" pos="0 0 0" size="0.005" rgba="1 0 0 1"/>
            <geom type="mesh" contype="0" conaffinity="0" group="1" density="0" rgba="1 1 1 1" mesh="right_chassis_wheel_link"/>
            <geom type="mesh" rgba="1 1 1 1" mesh="right_chassis_wheel_link" class="collision"/>
          </body>
        </body>
      </body>
      <body name="gimbal_yaw_link" pos="0 0 0.179">
        <inertial pos="0.0063949 0.01356 0.072584" quat="0.414713 0.909952 0.000280505 0.000204462" mass="0.70223" diaginertia="0.0011712 0.000967244 0.000603176"/>
        <joint name="gimbal_yaw_joint" pos="0 0 0" axis="0 0 1" class='gimbal_yaw_joint'/>
        <geom type="mesh" contype="0" conaffinity="0" group="1" density="0" rgba="1 1 1 1" mesh="gimbal_yaw_link"/>
        <body name="gimbal_pitch_motor_link" pos="0 0.04735 0.068">
          <inertial pos="-0.00079938 0.00028082 -0.00010689" quat="0.500644 0.499443 0.503381 0.496508" mass="0.29161" diaginertia="0.000164044 0.000103996 9.58677e-05"/>
          <joint name="gimbal_pitch_motor_joint" pos="0 0 0" axis="0 1 0" class='gimbal_pitch_joint'/>
          <geom type="mesh" contype="0" conaffinity="0" group="1" density="0" rgba="0.89412 0.9098 0.92549 1" mesh="gimbal_pitch_motor_link"/>
          <body name="gimbal_pitch_motor_chrild1_link" pos="-0.05 0.02585 0">
            <inertial pos="5.30454e-05 0.00258291 0.0325818" quat="0.704475 -0.00054886 0.00288271 0.709723" mass="0.0139252" diaginertia="8.65307e-06 8.23512e-06 4.85241e-07"/>
            <joint name="gimbal_pitch_motor_chrild1_joint" pos="0 0 0" axis="0 1 0"/>
            <site name="gimbal_pitch_motor_chrild1_site1" pos="0 -0.00285 0.067" size="0.005" rgba="1 0 0 1"/>
            <geom type="mesh" contype="0" conaffinity="0" group="1" density="0" rgba="0.50196 0.50196 0.50196 1" mesh="gimbal_pitch_motor_chrild1_link"/>
            <geom pos="0 -0.00285 0.067" quat="1 0 0 0" type="mesh" contype="0" conaffinity="0" group="1" density="0" rgba="0.772549 0.752941 0.733333 1" mesh="gimbal_pitch_motor_chrild2_link"/>
          </body>
        </body>
        <body name="gimbal_pitch_link" pos="0 0.043 0.135">
          <inertial pos="0.00570445 -0.0357203 0.0241585" quat="-0.00263437 0.642914 0.00278066 0.765929" mass="1.26308" diaginertia="0.00233617 0.00190761 0.00110017"/>
          <joint name="gimbal_pitch_joint" pos="0 0 0" axis="0 1 0" range="-0.43633 0.43633"/>
          <site name="gimbal_pitch_site1" pos="-0.05 0.02735 0.0" size="0.005" rgba="1 0 0 1"/>
          <geom type="mesh" contype="0" conaffinity="0" group="1" density="0" rgba="1 1 1 1" mesh="gimbal_pitch_link"/>
          <body name="left_frition_wheel_link" pos="0.07 -0.006 0.0161">
            <inertial pos="0 0 -0.0096337" quat="0.445654 0.548993 -0.445654 0.548993" mass="0.0352426" diaginertia="2.16795e-05 1.22606e-05 1.21007e-05"/>
            <joint name="left_frition_wheel_joint" pos="0 0 0" axis="0 0 1" class='frition_wheel_joint'/>
            <geom type="mesh" contype="0" conaffinity="0" group="1" density="0" rgba="1 1 1 1" mesh="left_frition_wheel_link"/>
          </body>
          <body name="right_frition_wheel_link" pos="0.07 -0.08 0.0161">
            <inertial pos="0 0 -0.0096337" quat="0.445654 0.548993 -0.445654 0.548993" mass="0.0352426" diaginertia="2.16795e-05 1.22606e-05 1.21007e-05"/>
            <joint name="right_frition_wheel_joint" pos="0 0 0" axis="0 0 1" class='frition_wheel_joint'/>
            <geom type="mesh" contype="0" conaffinity="0" group="1" density="0" rgba="1 1 1 1" mesh="right_frition_wheel_link"/>
          </body>
        </body>
      </body>
      <body name="feeder_desk_link" pos="0 0 0.076">
        <inertial pos="1.8898e-08 -8.1704e-09 -0.0047462" quat="0.270598 0.653281 -0.270598 0.653281" mass="0.069902" diaginertia="0.00014644 7.3556e-05 7.3556e-05"/>
        <joint name="feeder_desk_joint" pos="0 0 0" axis="0 0 1" class='feeder_desk_joint'/>
        <geom type="mesh" contype="0" conaffinity="0" group="1" density="0" rgba="1 1 1 1" mesh="feeder_desk_link"/>
      </body>
    </body>
  </worldbody>

  <equality>
      <connect name="Left_loop1" site1="left_front_knee_site1" site2="left_chassis_wheel_site1" solref="0.001 1" solimp="0.99 0.99 0.01 0.5 2"/>
      <connect name="Right_loop1" site1="right_front_knee_site1" site2="right_chassis_wheel_site1" solref="0.001 1" solimp="0.99 0.99 0.01 0.5 2"/>
      <connect name="Gimbal_pitch_loop1" site1="gimbal_pitch_motor_chrild1_site1" site2="gimbal_pitch_site1" solref="0.001 1" solimp="0.99 0.99 0.01 0.5 2"/>
  </equality>

  <actuator>
      <!-- 底盘机构电机 -->
      <motor name="left_front_hip_motor" joint="left_front_hip_joint" gear="1" ctrllimited="true"  class='Motorevo_PA100_motor'/>
      <motor name="left_rear_hip_motor"  joint="left_rear_hip_joint"  gear="1" ctrllimited="true"  class='Motorevo_PA100_motor'/>
      <motor name="left_chassis_wheel_motor" joint="left_chassis_wheel_joint" gear="1" ctrllimited="true" class='KTECH_MF9025V2_motor'/>
      <motor name="right_front_hip_motor" joint="right_front_hip_joint" gear="1" ctrllimited="true" class='Motorevo_PA100_motor'/>
      <motor name="right_rear_hip_motor"  joint="right_rear_hip_joint"  gear="1" ctrllimited="true" class='Motorevo_PA100_motor'/>
      <motor name="right_chassis_wheel_motor" joint="right_chassis_wheel_joint" gear="1" ctrllimited="true" class='KTECH_MF9025V2_motor'/>
      <!-- 云台机构电机 -->
      <motor name="gimbal_yaw_motor"  joint="gimbal_yaw_joint" gear="1" ctrllimited="true" class='DJI_GM6020_motor'/>
      <motor name="gimbal_pitch_motor"  joint="gimbal_pitch_motor_joint" gear="1" ctrllimited="true" class='DJI_GM6020_motor'/>
      <!-- 发射机构电机 -->
      <motor name="left_frition_wheel_motor"  joint="left_frition_wheel_joint" gear="1" ctrllimited="true" class='DJI_M3508_motor'/>
      <motor name="right_frition_wheel_motor"  joint="right_frition_wheel_joint" gear="1" ctrllimited="true" class='DJI_M3508_motor'/>
      <motor name="feeder_desk_motor"  joint="feeder_desk_joint" gear="1" ctrllimited="true" class='DJI_M2006_motor'/>
  </actuator>

  <sensor>
    <jointpos name="left_front_hip_pos" joint="left_front_hip_joint" />
    <jointpos name="left_rear_hip_pos" joint="left_rear_hip_joint" />
    <jointpos name="left_chassis_wheel_pos" joint="left_chassis_wheel_joint" />
    <jointpos name="right_front_hip_pos" joint="right_front_hip_joint" />
    <jointpos name="right_rear_hip_pos" joint="right_rear_hip_joint" />
    <jointpos name="right_chassis_wheel_pos" joint="right_chassis_wheel_joint" />
    <jointpos name="gimbal_yaw_pos" joint="gimbal_yaw_joint" />
    <jointpos name="gimbal_pitch_pos" joint="gimbal_pitch_motor_joint" />
    <jointpos name="left_frition_wheel_pos" joint="left_frition_wheel_joint" />
    <jointpos name="feeder_desk_pos" joint="feeder_desk_joint" />

    <jointvel name="left_front_hip_vel" joint="left_front_hip_joint" />
    <jointvel name="left_rear_hip_vel" joint="left_rear_hip_joint" />
    <jointvel name="left_chassis_wheel_vel" joint="left_chassis_wheel_joint" />
    <jointvel name="right_front_hip_vel" joint="right_front_hip_joint" />
    <jointvel name="right_rear_hip_vel" joint="right_rear_hip_joint" />
    <jointvel name="right_chassis_wheel_vel" joint="right_chassis_wheel_joint" />
    <jointvel name="gimbal_yaw_vel" joint="gimbal_yaw_joint" />
    <jointvel name="gimbal_pitch_vel" joint="gimbal_pitch_motor_joint" />
    <jointvel name="left_frition_wheel_vel" joint="left_frition_wheel_joint" />
    <jointvel name="feeder_desk_vel" joint="feeder_desk_joint" />

    <jointactuatorfrc name="left_front_hip_torque" joint="left_front_hip_joint" noise="0.01"/>
    <jointactuatorfrc name="left_rear_hip_torque" joint="left_rear_hip_joint" noise="0.01"/>
    <jointactuatorfrc name="left_chassis_wheel_torque" joint="left_chassis_wheel_joint" noise="0.01"/>
    <jointactuatorfrc name="right_front_hip_torque" joint="right_front_hip_joint" noise="0.01"/>
    <jointactuatorfrc name="right_rear_hip_torque" joint="right_rear_hip_joint" noise="0.01"/>
    <jointactuatorfrc name="right_chassis_wheel_torque" joint="right_chassis_wheel_joint" noise="0.01"/>
    <jointactuatorfrc name="gimbal_yaw_torque" joint="gimbal_yaw_joint" noise="0.01"/>
    <jointactuatorfrc name="gimbal_pitch_torque" joint="gimbal_pitch_motor_joint" noise="0.01"/>
    <jointactuatorfrc name="left_frition_wheel_torque" joint="left_frition_wheel_joint" noise="0.01"/>
    <jointactuatorfrc name="feeder_desk_torque" joint="feeder_desk_joint" noise="0.01"/>

    <framequat name="chassis_imu_quat" objtype="site" objname="imu" />
    <gyro name="chassis_imu_gyro" site="imu" />
    <accelerometer name="chassis_imu_acc" site="imu" />
    
    <framepos name="frame_pos" objtype="site" objname="imu" />
    <framelinvel name="frame_vel" objtype="site" objname="imu" />
  </sensor>  

</mujoco>
